Workbook

Sheet README
B2: Index of this spreadsheet
B4: Electricity prices | C4: =HYPERLINK("#'" & B4 & "'!A1", B4) -> Electricity prices
B5: Gas prices | C5: =HYPERLINK("#'" & B5 & "'!A1", B5) -> Gas prices
B18: Other references
B20: Rewiring Aotearoa model | C20: https://docs.google.com/spreadsheets/d/1huoy4UncVW_fkBJAA0xj_LGKF6sLm3SWd1cHOTh1kAA/edit?gid=0#gid=0
B22: EECA review and checks | C22: Final checks on technical report - March 2024.xlsx
C23: See "Wood" tab for pricing, density and NCV data used in the calculator
B31: Powerswitch data | C31: tariffDataReport_240903__EECA_analysis.xlsx
B33: Moneyhub data | C33: moneyhub_power_comparison_july_2024_updated.xlsx
B37: Space heating
B39: COPs for air-air HPs | C39: 20240805 - AC HSPF vs climate.xlsx
B42: Hot water
B44: Gas water heater registration data | C44: 20241031 - Gas water heater product data for Gareth.xlsx
B49: Driving
B51: Gen Less EV page | C51: https://genless.govt.nz/for-everyone/on-the-move/consider-electric-vehicles/why-buy-an-ev/
C52: https://genless.govt.nz/assets/Shared-Resources/electric-vehicle-running-cost-calculations.xlsx
B54: MVR data | C54: MVR--12-fields--2023-and-2024-to-September.xlsx
B56: MIA segmentation report | C56: MIA Common Segmentation Report October 2024.xlsx
B58: Webstructure fuel economy data | C58: CurrentNZnewFC_20241118.xlsx
B61: Number of residents vs number of rooms
B63: Ad-hoc analysis | C63: Census 2018 - Number of usual residents in household by number of rooms.xlsx

Sheet Back end
C3: TIMES-NZ residential energy use paper | D3: Rewiring
B4: Space heating | C4: Regionalisation based on floor area (detached/joined) and climate HDD | D4: Percentage according to climate. How derived?
B5: Water heating | C5: Regionalisation based on occupancy | D5: Assumed percentage
B6: Cooking | C6: None | D6: Assumed percentage
B7: Vehicle | C7: N/A | D7: Number of cars and assumed percentage
B15: Space heating | C15: Impact = Medium
B17: Energy service demand | C17: Warm house
C18: Temperature x time x floor area
C19: Climate
B21: Efficiency | C21: Thermal envelope
C22: Heater efficiency
B24: Fuel use | C24: Unknown
B26: Determinant | C26: Include (yes/no/maybe/comment) | D26: Question | E26: Algorithm | F26: Evidence | G26: Discussion
B27: Interior temperature | C27: No - most houses close to average
B28: Climate | C28: Yes | D28: Region | E28: HDD relative to NZ average HDD | F28: Theory (linear relationship)
B29: Time i.e. heating schedules | C29: Yes/maybe | D29: Home during day? | E29: ? | F29: eCubed H1/deep retrofit
B30: Floor area | C30: Maybe | D30: Area or number of bedrooms | E30: Linear scaling? | F30: Theory (linear relationship)
B31: Thermal envelope quality | C31: Maybe | D31: Age and/or characteristics of house | E31: ? | F31: eCubed H1/deep retrofit
B32: Number of people | C32: Maybe/no | D32: How many people | E32: Assume correlation with area heated? | F32: ?
B34: Notes
B36: Lowest cost space heating option is generally HP, so limited value in high fidelity here?
B37: How many heat pumps do we assume? Mix of HPs and electric?
B38: If being explicit about main living area, develop standard model and run through heating assessment tool.
B40: More sophisticated tools
B42: Tenancy services heating assessment tool (for deisgn loads)
B43: EECA/E3 HP seasonal efficiency algorithm
B45: Water heating | C45: Impact = Medium
B47: Energy service demand | C47: Showering/washing
C48: Temperature x volume
C49: Climate?
B51: Efficiency | C51: Appliance efficiency (inc shower head)
B53: Fuel use | C53: Largely unknown. 45 kg gas bottle use would be closest
B55: Determinant | C55: Include (yes/no/maybe/comment) | D55: Question | E55: Algorithm | F55: Evidence | G55: Discussion
B56: Number of people | C56: Yes | D56: As per determinant
B57: Number of showers per day (per person, or just total) | C57: Yes | D57: As per determinant | E57: Linear scaling from assumed average? Via top down/bottom up reconciliation? | F57: BRANZ SR469/UoA
B58: Duration of shower | C58: Maybe | D58: Lump into high/low/average question? | E58: Percentage scaling | F58: BRANZ SR469/UoA | G58: Natural language questions rather than qualititative answers (Do you use a lot of hot water? Low / Medium / High user)
B59: Shower flow rate | C59: Maybe
B60: Number of baths | C60: Yes/maybe | E60: Assume bath = 2x shower?
B61: Other water use (e.g. laundry) | C61: Maybe
B62: Climate | C62: Yes | D62: Region | E62: TBC. From old tool or standard? | F62: Theory (linear relationship)
...

Sheet Front end
A1: Options | B1: Question | C1: Answer options | D1: Algorithm impact | E1: Notes/Consideration
B2: How many people in your house | C2: 1 | D2: Hot water | E2: EECA to confirm the max household number should be.
C3: 2 | D3: Cooking
C4: 3 | D4: Heating
C5: 4
C6: 5
C7: 6+
B9: Where do you live? | C9: Region (list) | D9: Heating | E9: EECA to confirm whether this will also have an overall impact via power bill pricing.
D10: Hot water
B12: What best describes your house? | C12: Well insulated | D12: Heating | E12: Alternative answers: Warm and dry, Cold and drafty, Somewhere in between.
C13: Not well insulated
C14: Somewhere in between
B16: What are your main appliances? | C16: Heating: | D16: Heating | E16: This could alternatively be framed fuel first and appliances second. Note that there are some technologies not covered in the tool, so if a user can’t answer a question they must still be able to get to the end (eg, solar hot water systems) – need to figure out how this situation is shown in results/what assumptions are.
C17: Piped gas | D17: Hot water
C18: Bottled gas (LPG) | D18: Cooking
C19: Heat pump
C20: Other electric | E20: Wording to be finalised
C21: Wood
C22: Hot water:
C23: Piped gas
C24: Bottled gas (LPG)
C25: Hot water heat pump
C26: Traditional electric hot water cylinder
C27: Cooking:
C28: Piped gas
C29: Bottled gas (LPG)
C30: Electric induction
C31: Other electric | E31: Could have "Electric resistance" and Electric induction" here but have a tooltip here explaining the difference: "If your electric stove glows red hot while cooking = electric resistance, if it doesn't = electric induction".
B33: Are people in your household home during the day during the week? (eg, working from home) | C33: Rarely | D33: Heating, and potentially solar | E33: Question and answer to be user tested (algorithm can be adapted to suit)
C34: Sometimes
C35: Often
C36: Always
B38: Hot water use: | C38: Low | D38: Hot water | E38: EECA can provide text on what low/medium/high usage looks like on per person basis. Could alternatively be "Household shower/bath use"
C39: Medium
C40: High
B42: How many cars | C42: 1 | D42: Driving | E42: EECA to confirm the max number of cars.
C43: 2
C44: etc.
B46: What type of fuel | C46: Petrol | D46: Driving | E46: For each car
C47: Diesel
...

Sheet Front end (V2)
A1: Question | B1: Answer options | C1: Tooltip | D1: Notes/Consideration
A2: Your home
A4: Where do you live? | B4: Postcode or Address Lookup | C4: We use this information to estimate electricity prices in your area, and to estimate energy use for heating and hot water.
A6: How many people in your house | B6: 1 | C6: We use this information to estimate energy use for hot water and cooking.
B7: 2
B8: 3
B9: 4
B10: 5
B11: 6+
A13: Do you currently have solar panels? | B13: Yes | C13: This tool only considers solar panels which produce electricity | D13: Defaults to no. If users leave as no, then there needs to be a toggle button that is persistent that allows users to 'add solar' to the results displayed for each appliance.
B14: No
A16: Heating
A18: How do you heat your main living area? | B18: Piped gas heater
B19: Bottled gas heater
B20: Heat pump
B21: Heat pump (ducted)
B22: Electric heater(s)
B23: Wood burner
A25: What best describes the insulation in your house? | B25: Well insulated | C25: A modern house with full insulation and double glazing. This will have been built after 2008, or upgraded to an equivalent standard.
B26: Not well insulated | C26: An old house that has full coverage of floor and ceiling insulation, but no wall insulation and single glazing.
B27: Somewhere in between | C27: An old house with some floor and ceiling insulation but no wall insulation and single glazing.
A29: Do you have heating on during the day? | B29: Yes - weekdays and weekends | C29: In all cases we assume that you have the heating on most mornings and evenings during the colder months.
B30: Weekends only
B31: Only occasionally
A33: Water heating
A35: How do you heat your water? | B35: Piped gas instantaneous | C35: Many people call instantaneous gas systems continuous flow or 'infinity' systems.
B36: Bottled gas instantaneous
B37: Gas hot water cylinder
B38: Electric hot water cylinder
B39: Hot water heat pump
A41: Would you describe your hot water use as low, medium or high? | B41: Low | C41: Less frequent and/or shorter showers
B42: Medium | C42: Approximately 1 average length shower (7 minutes) per person per day
B43: High | C43: More frequent and/or longer showers
A45: Cooking
A47: What kind of cooktop do you use? | B47: Piped gas | C47: This tool doesn't consider gas ovens.
B48: Bottled gas (LPG)
B49: Electric induction | C49: Induction cooktops need magnetic pans.
B50: Electric coil or radiant ceramic | C50: Could have "Electric resistance" and Electric induction" here but have a tooltip here explaining the difference: "If your electric stove glows red hot while cooking = electric resistance, if it doesn't = electric induction".
A52: Driving
A54: What type of car / Car size | B54: Small | C54: Hatchback or compact car | D54: A visual prompt would help.
...

Sheet Copy of earlier ideation
A1: Parameters | B1: Variables | C1: Modifiers
A2: Driving | B2: How far do you drive, # of vehicles, vehicle type (EV, ICE, Hybrid), charging type, frequency of use / distance driven per day. | C2: Age of car, possibly? Power plan.
A3: Home heating | B3: Region, climate data, # of people in house, sq/footage of house; type (LPG, piped gas, electric resistance, electric heat pump, wood burner), age of house (pre-200 or post-2000), insulation level (ceiling, walls, underfloor, glazing). Do you have a fire? | C3: how many heat pumps added impact of turning off gas supply completely
A4: Water heating | B4: # of people in house, type (LPG, piped gas, electric resistance, electric heat pump); how long spent in shower, how often you use shower/bath. High or low water use? | C4: added impact of turning off gas supply completely. Size of water cylinder could be a factor.
A5: Cooking | B5: Type (LPG, piped gas, electric resistance, induction) | C5: added impact of turning off gas supply completely
A6: Rooftop solar | C6: Not taking into account panels' age/degradation/inverter age etc.
A7: Power plan | B7: Off peak rates, overnight rates, fixed/variable | C7: Compare optimal current plan versus your optimal power plan (given new electrified appliances). Powerswitch partnership? MBIE partnership?
A8: Battery | B8: Yes / no | C8: For phase 2?
A9: Modifiers on all parameters | B9: Time as a factor (15 year versus 1 year), Upfront costs (include or not include), Gas line/bottle charges. Replacement of appliance opportunity (doing renovations etc). Age of appliances. Emissions influence ($12 billion cost of offsets if we don't meet Paris argets). | C9: Emissions - this may persuade some people to change when cost savings are otherwise negligible.

Sheet SH - Ideas
B2: Space heating calculation
B4: Utilise some of the concepts previously used for the WKH HP sizing methodology. See files in this folder:
B6: Residential - Space Heating - Heat Load Calculation
B8: In particular:
B10: Heat Pump Sizing Method Report.docx
B11: Scenarios for WKH Heat Pump sizing.docx
B12: HP sizing v2.xlsx
B13: WKH Sizing Table Scenarios.xlsx
B15: Central case was:
B17: 40 m^2 floor area
B18: 2.4 m ceiling height
B19: Two external walls
... B22: For electrify tool:
C24: "Well insulated" | D24: "Somewhere in between" | E24: "Not well insulated"
B25: Floor | C25: 1.3 | D25: 1.3 | E25: 0.5
B26: Wall | C26: 1.9 | D26: 0.5 | E26: 0.5
B27: Ceiling | C27: 2.9 | D27: 2.9 | E27: 1.9
B28: Windows | C28: 0.26 | D28: 0.15 | E28: 0.15
B30: "Well insulated" = 2008 Building Code
B31: "Somewhere in between" = WKH retrofit (based on 2008 Building Code) to pre-1978 building with single glazing.
B32: "Not well insulated" = pre-1978 but with retrofit ceiling insulation to 1978 standard.
B34: Tool tip descriptions:
B36: Well insulated | E36: A modern house with full insulation and double glazing. This will have been built after 2008, or upgraded to an equivalent standard.
B37: Somewhere in between | E37: An old house that has full coverage of floor and ceiling insulation, but no wall insulation and single glazing.
B38: Not well insulated | E38: An old house with some floor and ceiling insulation but no wall insulation and single glazing.
B40: Notes
B42: Climate zones
B44: 16 Regional Council regions or 18 NIWA climate zones
B45: Preferably 18 to align with other tools?
B46: … but climate zones are less obvious e.g. how do we get Upper Hutt residents to identify as being in Wairarapa climate zone?
B47: Note Heating Assessment Tool asks for Region, and then "Council Area". Could do something like this?
B49: Heating Degree Days and bottom-up to top-down reconciliation
B51: Alignment with Heating Assessment Tool - Not critical given scaling which will be used for reconciliation?
B52: Alignment with ZERL?
B54: Default R-values copied from "Default R-values" tab of:
B56: Heater sizing spreadsheet v1.0.xlsm
B58: Climate zone | C58: 1 or 2 | D58: 1 or 2 | E58: 1 or 2 | F58: 1 or 2
B59: Building element | C59: 1977 or earlier | D59: From 1978 to 2000 | E59: From 2001 to 2008 | F59: From 2009 onwards
B60: Ext Floor | C60: 0.5 | D60: 0.9 | E60: 1.3 | F60: 1.3
B61: Int Floor | C61: 0.5 | D61: 0.5 | E61: 0.5 | F61: 0.5
...

Sheet SH - Time bands
B2: Time bands used for heating schedules in Deep Retrofit study
B4: The following Python script is used to segment the hourly data into time bands
B5: Analyse_baseline_for_electrify_tool__v4.py
B8: NZST OR NZDT | F8: NZST | I8: NZDT | L8: Logic of eso file is effectively:
B10: Start time | C10: End time | D10: Heating time period | F10: Hour (as per eso) | I10: Hour (as per eso) | L10: Simulation runs in NZST throughout year.
B11: 0 | C11: =B11 + 1 / 24 -> 0.041666667 | F11: 1 | I11: 1 | L11: When daylight saving time is in effect, the heating schedule shifts an hour earlier.
B12: =B11 + 1 / 24 -> 0.041666667 | C12: =B12 + 1 / 24 -> 0.083333333 | F12: 2 | I12: 2
B13: =B12 + 1 / 24 -> 0.083333333 | C13: =B13 + 1 / 24 -> 0.125 | F13: 3 | I13: 3
B14: =B13 + 1 / 24 -> 0.125 | C14: =B14 + 1 / 24 -> 0.16666667 | F14: 4 | I14: 4
B15: =B14 + 1 / 24 -> 0.16666667 | C15: =B15 + 1 / 24 -> 0.20833333 | F15: 5 | I15: 5
B16: =B15 + 1 / 24 -> 0.20833333 | C16: =B16 + 1 / 24 -> 0.25 | F16: 6 | I16: 6
B17: =B16 + 1 / 24 -> 0.25 | C17: =B17 + 1 / 24 -> 0.29166667 | F17: 7 | I17: 7 | J17: Morning
B18: =B17 + 1 / 24 -> 0.29166667 | C18: =B18 + 1 / 24 -> 0.33333333 | D18: Morning | F18: 8 | G18: Morning | I18: 8 | J18: Morning
B19: =B18 + 1 / 24 -> 0.33333333 | C19: =B19 + 1 / 24 -> 0.375 | D19: Morning | F19: 9 | G19: Morning | I19: 9 | J19: Day
B20: =B19 + 1 / 24 -> 0.375 | C20: =B20 + 1 / 24 -> 0.41666667 | D20: Day | F20: 10 | G20: Day | I20: 10 | J20: Day
B21: =B20 + 1 / 24 -> 0.41666667 | C21: =B21 + 1 / 24 -> 0.45833333 | D21: Day | F21: 11 | G21: Day | I21: 11 | J21: Day
B22: =B21 + 1 / 24 -> 0.45833333 | C22: =B22 + 1 / 24 -> 0.5 | D22: Day | F22: 12 | G22: Day | I22: 12 | J22: Day
B23: =B22 + 1 / 24 -> 0.5 | C23: =B23 + 1 / 24 -> 0.54166667 | D23: Day | F23: 13 | G23: Day | I23: 13 | J23: Day
B24: =B23 + 1 / 24 -> 0.54166667 | C24: =B24 + 1 / 24 -> 0.58333333 | D24: Day | F24: 14 | G24: Day | I24: 14 | J24: Day
B25: =B24 + 1 / 24 -> 0.58333333 | C25: =B25 + 1 / 24 -> 0.625 | D25: Day | F25: 15 | G25: Day | I25: 15 | J25: Day
B26: =B25 + 1 / 24 -> 0.625 | C26: =B26 + 1 / 24 -> 0.66666667 | D26: Day | F26: 16 | G26: Day | I26: 16 | J26: Day
B27: =B26 + 1 / 24 -> 0.66666667 | C27: =B27 + 1 / 24 -> 0.70833333 | D27: Day | F27: 17 | G27: Day | I27: 17 | J27: Evening
B28: =B27 + 1 / 24 -> 0.70833333 | C28: =B28 + 1 / 24 -> 0.75 | D28: Evening | F28: 18 | G28: Evening | I28: 18 | J28: Evening
B29: =B28 + 1 / 24 -> 0.75 | C29: =B29 + 1 / 24 -> 0.79166667 | D29: Evening | F29: 19 | G29: Evening | I29: 19 | J29: Evening
... B32: =B31 + 1 / 24 -> 0.875 | C32: =B32 + 1 / 24 -> 0.91666667 | D32: Evening | F32: 22 | G32: Evening | I32: 22 | J32: Evening
B33: =B32 + 1 / 24 -> 0.91666667 | C33: =B33 + 1 / 24 -> 0.95833333 | D33: Evening | F33: 23 | G33: Evening | I33: 23
B34: =B33 + 1 / 24 -> 0.95833333 | C34: =B34 + 1 / 24 -> 1 | F34: 24 | I34: 24

Sheet SH - Final
B2: Space heating calculation
B4: Need to factor Rewiring Aotearoa numbers by:
B6: Living area
B7: Climate zone
B8: Home insulation standard
B9: Time slices
B11: Regional COP data (HSPF) is from this spreadsheet:
B12: 20240805 - AC HSPF vs climate.xlsx
B15: Data from Machines tab of Rewiring spreadsheet and EEUD
B17: Note 365.25 days per year in calculation
B19: Options for homes > | C19: If Ngas | D19: If LPG | E19: If Wood | F19: If diesel boiler | G19: If resistive | H19: If heat pump on grid
B20: kWh/day | C20: 11.644 | D20: 11.644 | E20: 14.331 | F20: 12.849 | G20: 9.315 | H20: 2.662
B21: kWh/year | C21: 4253 | D21: 4253 | E21: 5234 | F21: 4693 | G21: 3402 | H21: 972
B23: Efficiency | C23: 0.8 | D23: 0.8 | E23: 0.65 | G23: 1 | H23: 3.5
B25: ESD | C25: =C21 * C23 -> 3402.4 | D25: =D21 * D23 -> 3402.4 | E25: =E21 * E23 -> 3402.1 | F25: =F21 * F23 -> 0 | G25: =G21 * G23 -> 3402 | H25: =H21 * H23 -> 3402
B27: Values above are determined from RBS and:
B29: Number of homes | C29: 1920300 | D29: Misc tab, cell B2
B31: National ESD | C31: =C25 * C29 / 1000000 -> 6533.6287 | D31: GWh
C32: =C31 * 3.6 -> 23521.063 | D32: TJ | E32: EEUD has 20,524 TJ of fuel use for residential space heating in 2022. Given heat pump usage, makes sense that ESD > fuel use.
B35: Proportion of heat used for living areas
B37: Values above are for a whole home
B38: Proportion of this which is living area (inc kitchen and dining) is derived from Deep Retrofit report via this Python script:
B39: Analyse_baseline_for_electrify_tool__v4.py
B41: LKD | C41: 0.62925887 | E41: This is heat (energy service demand) proportion.
B44: Climate zone
B46: Data tables from TIMES-NZ paper
B48: Detached dwelling floor area | D48: 171 | E48: m^2
B49: Joined dwelling floor area | D49: 115 | E49: m^2
B51: Climate zone | C51: Climate zone code | D51: HDD (Tref = 18 OC) | E51: HDD (Tref = 16 OC) | F51: HDD (Tref = 14 OC) | I51: Climate zone | J51: Number of detached dwellings | K51: Number of joined dwellings | L51: Total by climate zone
B52: Northland | C52: NL | D52: 1024 | E52: 543 | F52: 220 | I52: Northland | J52: 59960 | K52: 7848 | L52: 67808 | O52: =J52 * $D$48 * D52 -> 10499235840 | P52: =K52 * $D$49 * D52 -> 924180480 | Q52: =O52 + P52 -> 11423416320
B53: Auckland | C53: AK | D53: 1165 | E53: 674 | F53: 317 | I53: Auckland | J53: 390206 | K53: 128320 | L53: 518526 | O53: =J53 * $D$48 * D53 -> 77734888290 | P53: =K53 * $D$49 * D53 -> 17191672000 | Q53: =O53 + P53 -> 94926560290
B54: Hamilton | C54: HN | D54: 1710 | E54: 1133 | F54: 693 | I54: Hamilton | J54: 117120 | K54: 15016 | L54: 132136 | O54: =J54 * $D$48 * D54 -> 34247059200 | P54: =K54 * $D$49 * D54 -> 2952896400 | Q54: =O54 + P54 -> 37199955600
B55: Bay of Plenty | C55: BP | D55: 1274 | E55: 798 | F55: 438 | I55: Bay of Plenty | J55: 79726 | K55: 10974 | L55: 90700 | O55: =J55 * $D$48 * D55 -> 17368628004 | P55: =K55 * $D$49 * D55 -> 1607800740 | Q55: =O55 + P55 -> 18976428744
B56: Rotorua | C56: RR | D56: 2146 | E56: 1511 | F56: 974 | I56: Rotorua | J56: 24057 | K56: 2306 | L56: 26363 | O56: =J56 * $D$48 * D56 -> 8828101062 | P56: =K56 * $D$49 * D56 -> 569097740 | Q56: =O56 + P56 -> 9397198802
B57: Taupo | C57: TP | D57: 2365 | E57: 1718 | F57: 1162 | I57: Taupo | J57: 27293 | K57: 2119 | L57: 29412 | O57: =J57 * $D$48 * D57 -> 11037698595 | P57: =K57 * $D$49 * D57 -> 576315025 | Q57: =O57 + P57 -> 11614013620
B58: New Plymouth | C58: NP | D58: 1646 | E58: 1028 | F58: 552 | I58: New Plymouth | J58: 58471 | K58: 7864 | L58: 66335 | O58: =J58 * $D$48 * D58 -> 16457598486 | P58: =K58 * $D$49 * D58 -> 1488576560 | Q58: =O58 + P58 -> 17946175046
B59: East Coast | C59: EC | D59: 1604 | E59: 1059 | F59: 636 | I59: East Coast | J59: 57600 | K59: 11677 | L59: 69277 | O59: =J59 * $D$48 * D59 -> 15798758400 | P59: =K59 * $D$49 * D59 -> 2153939420 | Q59: =O59 + P59 -> 17952697820
B60: Manawatu | C60: MW | D60: 1821 | E60: 1195 | F60: 689 | I60: Manawatu | J60: 67775 | K60: 11101 | L60: 78876 | O60: =J60 * $D$48 * D60 -> 21104525025 | P60: =K60 * $D$49 * D60 -> 2324715915 | Q60: =O60 + P60 -> 23429240940
B61: Wairarapa | C61: WI | D61: 2100 | E61: 1495 | F61: 994 | I61: Wairarapa | J61: 35692 | K61: 5284 | L61: 40976 | O61: =J61 * $D$48 * D61 -> 12816997200 | P61: =K61 * $D$49 * D61 -> 1276086000 | Q61: =O61 + P61 -> 14093083200
B62: Wellington | C62: WN | D62: 1930 | E62: 1289 | F62: 770 | I62: Wellington | J62: 90748 | K62: 38361 | L62: 129109 | O62: =J62 * $D$48 * D62 -> 29949562440 | P62: =K62 * $D$49 * D62 -> 8514223950 | Q62: =O62 + P62 -> 38463786390
...

Sheet SH - Regression model
A2: Typology | B2: Location | C2: source | D2: regression_local | E2: delta_local
A3: VillaBungalow | B3: Auckland | C3: 2016.3926 | D3: 2240.6126 | E3: 224.22007
B4: Wellington | C4: 3469.1661 | D4: 3621.1699 | E4: 152.00388
B5: Christchurch | C5: 4027.7029 | D5: 4331.1496 | E5: 303.44673
B6: Queenstown | C6: 4702.1604 | D6: 4806.8415 | E6: 104.68107
A7: State House | B7: Auckland | C7: 1564.6935 | D7: 1886.0484 | E7: 321.35494
B8: Wellington | C8: 2923.0018 | D8: 3125.7736 | E8: 202.77174
B9: Christchurch | C9: 3460.5967 | D9: 3837.8857 | E9: 377.28903
B10: Queenstown | C10: 4028.3862 | D10: 4153.8785 | E10: 125.49231
A11: 1970s House | B11: Auckland | C11: 2082.0463 | D11: 2408.802 | E11: 326.75572
B12: Wellington | C12: 3818.3389 | D12: 4079.7362 | E12: 261.39736
B13: Christchurch | C13: 4995.3102 | D13: 5412.0899 | E13: 416.77972
B14: Queenstown | C14: 5472.7823 | D14: 5426.5075 | E14: -46.274876
A15: Post 1978 House | B15: Auckland | C15: 2238.2604 | D15: 2695.3523 | E15: 457.09192
B16: Wellington | C16: 4278.7021 | D16: 4630.2924 | E16: 351.5903
B17: Christchurch | C17: 5901.7451 | D17: 6421.3985 | E17: 519.65339
B18: Queenstown | C18: 6200.524 | D18: 6534.7752 | E18: 334.25116
A21: Typology | B21: Location | C21: source | D21: regression_combined | E21: delta_combined
A22: VillaBungalow | B22: Auckland | C22: 2016.3926 | D22: 2181.453 | E22: 165.06047
B23: Wellington | C23: 3469.1661 | D23: 3558.7436 | E23: 89.577504
B24: Christchurch | C24: 4027.7029 | D24: 4270.4814 | E24: 242.77853
B25: Queenstown | C25: 4702.1604 | D25: 5004.5311 | E25: 302.37067
A26: State House | B26: Auckland | C26: 1564.6935 | D26: 1804.6402 | E26: 239.94669
B27: Wellington | C27: 2923.0018 | D27: 3048.4812 | E27: 125.47936
B28: Christchurch | C28: 3460.5967 | D28: 3727.2534 | E28: 266.65672
B29: Queenstown | C29: 4028.3862 | D29: 4420.9393 | E29: 392.55307
A30: 1970s House | B30: Auckland | C30: 2082.0463 | D30: 2461.5777 | E30: 379.53144
B31: Wellington | C31: 3818.3389 | D31: 4066.978 | E31: 248.63916
B32: Christchurch | C32: 4995.3102 | D32: 4928.4299 | E32: -66.880235
B33: Queenstown | C33: 5472.7823 | D33: 5753.7391 | E33: 280.95679
A34: Post 1978 House | B34: Auckland | C34: 2238.2604 | D34: 2974.2613 | E34: 736.00094
B35: Wellington | C35: 4278.7021 | D35: 4797.0363 | E35: 518.3342
B36: Christchurch | C36: 5901.7451 | D36: 5673.6424 | E36: -228.10277
B37: Queenstown | C37: 6200.524 | D37: 6521.2116 | E37: 320.6876
A40: Typology | B40: Location | C40: source | D40: regression_local | E40: regression_combined
A41: VillaBungalow | B41: Auckland | C41: 2016.3926 | D41: 2240.6126 | E41: 2181.453
B42: Wellington | C42: 3469.1661 | D42: 3621.1699 | E42: 3558.7436
B43: Christchurch | C43: 4027.7029 | D43: 4331.1496 | E43: 4270.4814
B44: Queenstown | C44: 4702.1604 | D44: 4806.8415 | E44: 5004.5311
A45: State House | B45: Auckland | C45: 1564.6935 | D45: 1886.0484 | E45: 1804.6402
...

Sheet WH - Evidence
B2: Whittaker et al. (2022) Residential Water Use in New Zealand – End Use Disaggregation 2.0
B4: https://www.waternz.org.nz/Resources/Article?Action=View&Article_id=2243
B6: P. 23: "An additional “high flow or outdoor use” category was also created, as it is difficult to differentiate between outdoor use and high-flow taps such as in a laundry tub."
B8: P. 35: "The increase in outdoor use in Spring and Summer is also to be expected, as is the increase in absolute volumes used for showers in these months (even if the relative contribution of shower events remained unchanged)."
B9: Above is opposite to GG's previous understanding that shower use went up in winter. May be specific demographic factors in that high shower use in winter was understood to be related to colder homes.
B11: Searched document for "bath". No references. Assume bath is in the "high flow" bucket.
K15: Use type | L15: Mean daily volume (litres) | M15: Median daily volume (litres) | N15: Standard Deviation (litres) | O15: 95% confidence interval in mean (litres)
K16: Dishwasher | L16: 6.1 | M16: 4.1 | N16: 6.1 | O16: [4.1, 8.1] | Q16: Dishwashers are most often internally heated so no draw from HW system.
K17: Washing Machine | L17: 54.1 | M17: 37.2 | N17: 51.9 | O17: [37.0, 71.1] | Q17: Normal/warm wash is 35 deg. Assume 50% of water use is cold (for e.g. rinse) and 50% is 35 degC.
K18: Toilet | L18: 80.7 | M18: 56.5 | N18: 55.2 | O18: [62.6, 98.8] | Q18: All cold
K19: Shower | L19: 102.1 | M19: 99.9 | N19: 61.5 | O19: [81.9, 122.3] | Q19: All 37 degC.
K20: Tap | L20: 46.3 | M20: 41.7 | N20: 31.9 | O20: [35.8, 56.8] | Q20: Assume 50/50 cold/40 degC.
K21: High Flow/Outdoor | L21: 54.2 | M21: 17.4 | N21: 87 | O21: [25.6, 82.8] | Q21: Assume winter use is laundry tubs/baths i.e. 0% outdoor. Assume this is constant through the year. Assume 50% is at 37 degC.
K22: Undefined | L22: 8.3 | M22: 1.2 | N22: 27.2 | O22: [-1.6, 18.1] | Q22: Ignore.
K29: Table 10 data reordered as per Table 9 data
L31: Average use frequency | N31: Per day | O31: Per week | Q31: Median use frequency | S31: Per day | T31: Per week | V31: Standard deviation | W31: 95% confidence interval in mean
K32: Dishwasher | L32: 4.2 | M32: per week | N32: =L32 / 7 -> 0.6 | O32: =N32 * 7 -> 4.2 | Q32: 2.9 | R32: per week | S32: =Q32 / 7 -> 0.41428571 | T32: =S32 * 7 -> 2.9 | V32: 3.4 | W32: [1.5, 4.2]
K33: Washing machine | L33: 3.4 | M33: per week | N33: =L33 / 7 -> 0.48571429 | O33: =N33 * 7 -> 3.4 | Q33: 2.2 | R33: per week | S33: =Q33 / 7 -> 0.31428571 | T33: =S33 * 7 -> 2.2 | V33: 3.5 | W33: [3.1, 5.2]
K34: Toilet | L34: 14.7 | M34: per day | N34: =L34 -> 14.7 | O34: =N34 * 7 -> 102.9 | Q34: 10.7 | R34: per day | S34: =Q34 -> 10.7 | T34: =S34 * 7 -> 74.9 | V34: 10.3 | W34: [11.5, 18.0]
K35: Shower | L35: 2 | M35: per day | N35: =L35 -> 2 | O35: =N35 * 7 -> 14 | Q35: 1.4 | R35: per day | S35: =Q35 -> 1.4 | T35: =S35 * 7 -> 9.8 | V35: 2.6 | W35: [1.2, 2.9]
K36: Tap | L36: 118.8 | M36: per day | N36: =L36 -> 118.8 | O36: =N36 * 7 -> 831.6 | Q36: 106.4 | R36: per day | S36: =Q36 -> 106.4 | T36: =S36 * 7 -> 744.8 | V36: 75.1 | W36: [95.1, 142.5]
K37: High Flow/Outdoor | L37: 2.8 | M37: per day | N37: =L37 -> 2.8 | O37: =N37 * 7 -> 19.6 | Q37: 2.9 | R37: per day | S37: =Q37 -> 2.9 | T37: =S37 * 7 -> 20.3 | V37: 3.4 | W37: [2.3, 4.5]
K40: Volume per use
K42: =K16 -> Dishwasher | L42: =L16 / N32 -> 10.166667
K43: =K17 -> Washing Machine | L43: =L17 / N33 -> 111.38235 | N43: "On average, an 8.5kg top loader uses nearly 135L of water per 3.5kg load, whereas an 8.5kg front loader swigs a more modest 64L."
K44: =K18 -> Toilet | L44: =L18 / N34 -> 5.4897959 | N44: https://www.consumer.org.nz/articles/how-to-save-water-in-the-laundry
K45: =K19 -> Shower | L45: =L19 / N35 -> 51.05
K46: =K20 -> Tap | L46: =L20 / N36 -> 0.38973064
K47: =K21 -> High Flow/Outdoor | L47: =L21 / N37 -> 19.357143
K50: Table 11 data reordered as per Table 9 data
L52: Average use frequency | N52: Per day | O52: Per week | Q52: Median use frequency | S52: Per day | T52: Per week | V52: Standard deviation | W52: 95% confidence interval in mean
K53: Dishwasher | L53: 1.6 | M53: per week | N53: =L53 / 7 -> 0.22857143 | O53: =N53 * 7 -> 1.6 | Q53: 1.2 | R53: per week | S53: =Q53 / 7 -> 0.17142857 | T53: =S53 * 7 -> 1.2 | V53: 1.4 | W53: [0.6, 1.5]
K54: Washing machine | L54: 1.3 | M54: per week | N54: =L54 / 7 -> 0.18571429 | O54: =N54 * 7 -> 1.3 | Q54: 1 | R54: per week | S54: =Q54 / 7 -> 0.14285714 | T54: =S54 * 7 -> 1 | V54: 1 | W54: [1.1, 2.1]
K55: Toilet | L55: 6.5 | M55: per day | N55: =L55 -> 6.5 | O55: =N55 * 7 -> 45.5 | Q55: 5.1 | R55: per day | S55: =Q55 -> 5.1 | T55: =S55 * 7 -> 35.7 | V55: 4.9 | W55: [4.8, 8.2]
K56: Shower | L56: 0.7 | M56: per day | N56: =L56 -> 0.7 | O56: =N56 * 7 -> 4.9 | Q56: 0.6 | R56: per day | S56: =Q56 -> 0.6 | T56: =S56 * 7 -> 4.2 | V56: 0.5 | W56: [0.5, 0.9]
K57: Tap | L57: 57.1 | M57: per day | N57: =L57 -> 57.1 | O57: =N57 * 7 -> 399.7 | Q57: 44.2 | R57: per day | S57: =Q57 -> 44.2 | T57: =S57 * 7 -> 309.4 | V57: 42.4 | W57: [42.3, 71.9]
K58: High Flow/Outdoor | L58: 1 | M58: per day | N58: =L58 -> 1 | O58: =N58 * 7 -> 7 | Q58: 1.2 | R58: per day | S58: =Q58 -> 1.2 | T58: =S58 * 7 -> 8.4 | V58: 1.4 | W58: [0.9, 1.6]
K61: Per dwelling (Table 10) divided by per person (Table 11)
K63: Dishwasher | L63: =L32 / L53 -> 2.625 | N63: Differences due to rounding, or source data?
K64: Washing machine | L64: =L33 / L54 -> 2.6153846
...

Sheet WH
B2: Water heating calculation | O2: Electric storage water heater efficiency | R2: AS/NZS 4692 MEPS level with TPR
O3: Element = 100% | P3: Scenario | Q3: Tank size | R3: Standing loss (kWh/day) | S3: Standing heatloss per year
B4: Low | C4: 3 showers + X loads of laundry | O4: Standing losses | P4: Low | Q4: 130L | R4: 1.56 | S4: =R4*365 -> 569.4
B5: Medium | C5: 5 showers per person per week + Y loads of laundry | P5: Medium | Q5: 180L | R5: 1.76 | S5: =R5*365 -> 642.4
B6: High | C6: 5 showers + 2 baths per person per week + Z loads of laundry | P6: High | Q6: 250L | R6: 2.16 | S6: =R6*365 -> 788.4
B8: Or | P8: kJ | Q8: kWh
O9: Energy to heat 1L of water by 1 degree | P9: 4.128 | Q9: 0.0011466667
B10: Low | C10: 5 showers x 5 minutes per person per week + X loads of laundry
B11: Medium | C11: 5 showers x 10 minutes per person per week + Y loads of laundry
B12: High | C12: ? | O12: Gas cylinder | P12: Scenario | Q12: Tank size | R12: Standing loss (kWh/day) | S12: Standing heatloss per year
P13: Low | Q13: 130 | R13: =Q13^(0.3261)*0.6099 -> 2.9827411 | S13: =R13*365 -> 1088.7005
B14: Or | P14: Medium | Q14: 180 | R14: =Q14^(0.3261)*0.6099 -> 3.3166756 | S14: =R14*365 -> 1210.5866
P15: High | Q15: 250 | R15: =Q15^(0.3261)*0.6099 -> 3.691704 | S15: =R15*365 -> 1347.472
B16: Low | C16: 5 showers x 5-7 minutes per person per week + X loads of laundry | P16: Pilot rate (W) | Q16: 50
B17: Medium | C17: 7 showers x 8-10 minutes per person per week + Y loads of laundry | P17: Electricty rate
B18: High | C18: 7 showers x 10-15 minutes per person per week + Z loads of laundry
O20: Gas instantaneous | P20: Assumed efficiency from AS 4552 | Q20: 0.75 | R20: better to take an average of existing products
B21: Medium water use scenario is informed by data | P21: Electricty rate
B22: Low and high also informed by data (if available) but designed/selected to give +/- 30-50% between scenarios. | P22: Pilot rate
B24: Product efficiency variation | S24: =R27/24 -> 0.13819482
R25: AS/NZS 4692 MEPS level based on AU MEPS
B26: HP COP by region? | O26: Heat pump water heater | P26: Scenario | Q26: Tank size | R26: Standing loss (kWh/day) | S26: Standing heatloss per year
P27: Low | Q27: 180 | R27: =Q27^(0.3261)*0.6099 -> 3.3166756 | S27: =R27*365 -> 1210.5866
P28: Medium | Q28: 250 | R28: =Q28^(0.3261)*0.6099 -> 3.691704 | S28: =R28*365 -> 1347.472
P29: High | Q29: 310 | R29: =Q29^(0.3261)*0.6099 -> 3.959968 | S29: =R29*365 -> 1445.3883
P31: Zone | Q31: Assumed average COP
P32: Northland | Q32: 4
P33: Auckland | Q33: 3.8
P34: Bay of Plenty | Q34: 3.6
P35: Waikato | Q35: 3.4
P36: Rotorua | Q36: 3.2
P37: Taupo | Q37: 3
P38: Taranaki | Q38: 2.8
P39: East Coast | Q39: 2.6
P40: Wairarapa | Q40: 2.4
P41: Manawatu | Q41: 2.2
P42: Wellington | Q42: 2
P43: Marlborough | Q43: 2
... P45: Canterbury | Q45: 2
P46: Queenstown | Q46: 2 | Z46: Need to add pilot light rate
...

Sheet WH (2)
B2: Water heating calculation
O4: Heat pump water heater COP estimate by climate zone
B5: Variable | C5: Value | D5: comment | F5: Heat pump water heater performance | O5: Zone | P5: Zone | Q5: Using AC HSPF and calculating it as a ratio of auckland to other regions, based on registration data | R5: COP | S5: Savings over electric % | X5: Calculation
B6: Energy to heat 1L of water by 1 degree (kWh) | C6: 0.0011466667 | D6: A fact | F6: EECA quote saving of 60% to 75% | G6: Hot water heat pumps in the home | EECA | O6: Auckland | P6: Auckland | Q6: 1 | R6: =G8 -> 3.0769231 | S6: =100-100/R6 -> 67.5 | X6: Region | Y6: Auckland
B7: Electricity price ($/kWh) | C7: 0.265 | D7: Global to tool | F7: Average of this | G7: =(60+75)/2 -> 67.5 | O7: fhsp_bay_of_plenty_tauranga | P7: Bay of Plenty | Q7: 0.96893544 | R7: =$R$6*Q7 -> 2.9813398 | S7: =100-100/R7 -> 66.458034 | X7: Number of people | Y7: 3
B8: Gas price ($/kWh) | C8: 0.1 | D8: Global to tool | F8: COP | G8: =1/(100-G7)*100 -> 3.0769231 | O8: fhsp_canterbury_christchurch | P8: Canterbury | Q8: 0.79751357 | R8: =$R$6*Q8 -> 2.4538879 | S8: =100-100/R8 -> 59.248342
B9: Gas daily charge ($/day) | C9: 1.37 | D9: Global to tool | O9: fhsp_central_otago_lauder | P9: Centreal Otago | Q9: 0.67008823 | R9: =$R$6*Q9 -> 2.0618099 | S9: =100-100/R9 -> 51.498924 | Y9: Energy consumption per year | AC9: Running cost per year | AG9: GHG emissions | AK9: Running cost over life
B10: Set point of hot water out of system/tank (degree C) | C10: 65 | D10: Global to tool | O10: fhsp_east_coast_napier | P10: East Coast | Q10: 0.91204716 | R10: =$R$6*Q10 -> 2.806299 | S10: =100-100/R10 -> 64.365878 | Y10: Electric | Z10: Gas storage | AA10: Gas instantaneous | AB10: Heat pump | AC10: Electric | AD10: Gas storage | AE10: Gas instantaneous | AF10: Heat pump | AG10: Electric | AH10: Gas storage | AI10: Gas instantaneous | AJ10: Heat pump | AK10: Electric | AL10: Gas storage | AM10: Gas instantaneous | AN10: Heat pump
B11: Gas system thermal efficiency | C11: 0.8 | D11: Based on MEPS being 75%, MBIE saying 95%, and Rinnai saying 90%: - https://rinnai.co.nz/water-heating/gas-hot-water-systems/residential-use/rinnai-infinity-a-series-internal-and-external - https://www.building.govt.nz/getting-started/smarter-homes-guides/water-and-waste/hot-water-options#:~:text=Gas%20is%20only%20used%20when,to%2095%20per%20cent%20efficient. | O11: fhsp_manawatu_paraparaumu | P11: Manawatu | Q11: 0.93060578 | R11: =$R$6*Q11 -> 2.8634024 | S11: =100-100/R11 -> 65.076512 | X11: Low | Y11: =VLOOKUP($Y$6,$B$36:$M$54,MATCH(_xlfn.CONCAT($X11," ",Y$10),$B$36:$M$36,0),FALSE)*365+J29*($C$10-VLOOKUP($Y$6,$B$37:$D$54,3,FALSE))*$C$6*52*$Y$7 -> 2023.0668 | Z11: =VLOOKUP($Y$6,$B$36:$M$54,MATCH(_xlfn.CONCAT($X11," ",Z$10),$B$36:$M$36,0),FALSE)*365+J29*(($C$10-VLOOKUP($Y$6,$B$37:$D$54,3,FALSE))*$C$6*(1/$C$11)*52*$Y$7) -> 4943.4191 | AA11: =(J29+L29)*(($C$10-VLOOKUP($Y$6,$B$37:$D$54,3,FALSE))*$C$6*(1/$C$11)*52*$Y$7)+$C$12*365 -> 2057.2418 | AB11: =VLOOKUP($Y$6,$B$36:$M$54,MATCH(_xlfn.CONCAT($X11," ",AB$10),$B$36:$M$36,0),FALSE)*365*1/VLOOKUP($Y$6,$B$37:$D$54,2,FALSE)+J29*($C$10-VLOOKUP($Y$6,$B$37:$D$54,3,FALSE))*(1/VLOOKUP($Y$6,$B$37:$D$54,2,FALSE)*$Y$7)*$C$6*52 -> 899.05295 | AC11: =Y11*$C$7 -> 536.11271 | AD11: =Z11*$C$8+$C$9*365 -> 994.39191 | AE11: =AA11*$C$8+$C$9*365 -> 705.77418 | AF11: =AB11*$C$7 -> 238.24903 | AG11: =Y11*$C$16 -> 260.97562 | AH11: =Z11*$C$15 -> 1038.118 | AI11: =AA11*$C$15 -> 432.02078 | AJ11: =AB11*$C$16 -> 115.97783 | AK11: =AC11*12 -> 6433.3525 | AL11: =AD11*12 -> 11932.703 | AM11: =AE11*12 -> 8469.2902 | AN11: =AF11*12 -> 2858.9884
B12: Electricity consumption (gas instantaneous) (kWh) | C12: 0.05 | D12: Based on registration data | O12: fhsp_nelson_marlborough_nelson | P12: Marlborough | Q12: 0.90334929 | R12: =$R$6*Q12 -> 2.7795363 | S12: =100-100/R12 -> 64.022776 | X12: Medium | Y12: =VLOOKUP($Y$6,$B$36:$M$54,MATCH(_xlfn.CONCAT($X12," ",Y$10),$B$36:$M$36,0),FALSE)*365+J30*($C$10-VLOOKUP($Y$6,$B$37:$D$54,3,FALSE))*$C$6*52*$Y$7 -> 3743.7294 | Z12: =VLOOKUP($Y$6,$B$36:$M$54,MATCH(_xlfn.CONCAT($X12," ",Z$10),$B$36:$M$36,0),FALSE)*365+J30*(($C$10-VLOOKUP($Y$6,$B$37:$D$54,3,FALSE))*$C$6*(1/$C$11)*52*$Y$7) -> 7354.4023 | AA12: =(J30+L30)*(($C$10-VLOOKUP($Y$6,$B$37:$D$54,3,FALSE))*$C$6*(1/$C$11)*52*$Y$7)+$C$12*365 -> 4200.578 | AB12: =VLOOKUP($Y$6,$B$36:$M$54,MATCH(_xlfn.CONCAT($X12," ",AB$10),$B$36:$M$36,0),FALSE)*365*1/VLOOKUP($Y$6,$B$37:$D$54,2,FALSE)+J30*($C$10-VLOOKUP($Y$6,$B$37:$D$54,3,FALSE))*(1/VLOOKUP($Y$6,$B$37:$D$54,2,FALSE)*$Y$7)*$C$6*52 -> 1485.7656 | AC12: =Y12*$C$7 -> 992.08829 | AD12: =Z12*$C$8+$C$9*365 -> 1235.4902 | AE12: =AA12*$C$8+$C$9*365 -> 920.1078 | AF12: =AB12*$C$7 -> 393.72788 | AG12: =Y12*$C$16 -> 482.94109 | AH12: =Z12*$C$15 -> 1544.4245 | AI12: =AA12*$C$15 -> 882.12139 | AJ12: =AB12*$C$16 -> 191.66376 | AK12: =AC12*12 -> 11905.059 | AL12: =AD12*12 -> 14825.883 | AM12: =AE12*12 -> 11041.294 | AN12: =AF12*12 -> 4724.7346
B13: Shower set point | C13: 37 | D13: What is the Ideal Temperature to Shower in? - Rheem Asia – Rheem Manufacturing Company | O13: fhsp_northland_kaitaia | P13: Northland | Q13: 0.99960237 | R13: =$R$6*Q13 -> 3.0756996 | S13: =100-100/R13 -> 67.487072 | X13: High | Y13: =VLOOKUP($Y$6,$B$36:$M$54,MATCH(_xlfn.CONCAT($X13," ",Y$10),$B$36:$M$36,0),FALSE)*365+J31*($C$10-VLOOKUP($Y$6,$B$37:$D$54,3,FALSE))*$C$6*52*$Y$7 -> 7144.001 | Z13: =VLOOKUP($Y$6,$B$36:$M$54,MATCH(_xlfn.CONCAT($X13," ",Z$10),$B$36:$M$36,0),FALSE)*365+J31*(($C$10-VLOOKUP($Y$6,$B$37:$D$54,3,FALSE))*$C$6*(1/$C$11)*52*$Y$7) -> 11932.619 | AA13: =(J31+L31)*(($C$10-VLOOKUP($Y$6,$B$37:$D$54,3,FALSE))*$C$6*(1/$C$11)*52*$Y$7)+$C$12*365 -> 8413.6962 | AB13: =VLOOKUP($Y$6,$B$36:$M$54,MATCH(_xlfn.CONCAT($X13," ",AB$10),$B$36:$M$36,0),FALSE)*365*1/VLOOKUP($Y$6,$B$37:$D$54,2,FALSE)+J31*($C$10-VLOOKUP($Y$6,$B$37:$D$54,3,FALSE))*(1/VLOOKUP($Y$6,$B$37:$D$54,2,FALSE)*$Y$7)*$C$6*52 -> 2576.5218 | AC13: =Y13*$C$7 -> 1893.1603 | AD13: =Z13*$C$8+$C$9*365 -> 1693.3119 | AE13: =AA13*$C$8+$C$9*365 -> 1341.4196 | AF13: =AB13*$C$7 -> 682.77829 | AG13: =Y13*$C$16 -> 921.57613 | AH13: =Z13*$C$15 -> 2505.8501 | AI13: =AA13*$C$15 -> 1766.8762 | AJ13: =AB13*$C$16 -> 332.37132 | AK13: =AC13*12 -> 22717.923 | AL13: =AD13*12 -> 20319.743 | AM13: =AE13*12 -> 16097.035 | AN13: =AF13*12 -> 8193.3395
B14: Washing machine set point | C14: 36 | D14: Based of the temperature of set point of washing machine standard | O14: fhsp_otago_dunedin | P14: Otago | Q14: 0.94142689 | R14: =$R$6*Q14 -> 2.8966981 | S14: =100-100/R14 -> 65.477935
B15: GHG emissions gas (kg/kWh) | C15: 0.21 | D15: Global to tool | O15: fhsp_queenstown_lakes_queenstown | P15: Queenstown | Q15: 0.73112237 | R15: =$R$6*Q15 -> 2.2496073 | S15: =100-100/R15 -> 55.547797 | X15: Calculation
B16: GHG emissions electricity (kg/kWh) | C16: 0.129 | D16: Global to tool | O16: fhsp_rotorua_rotorua | P16: Rotorua | Q16: 0.86199828 | R16: =$R$6*Q16 -> 2.6523024 | S16: =100-100/R16 -> 62.296908 | X16: Region | Y16: Centreal Otago
B17: Instantaneous start- up water (L) volume | C17: 2 | D17: From old hot water tool | O17: fhsp_southland_invercargill | P17: Southland | Q17: 0.8724485 | R17: =$R$6*Q17 -> 2.6844569 | S17: =100-100/R17 -> 62.748518 | X17: Number of people | Y17: 3
B18: Temperature difference indoor degree C | C18: 5 | D18: Guess | O18: fhsp_taranaki_new_plymouth | P18: Taranaki | Q18: 0.95251173 | R18: =$R$6*Q18 -> 2.9308053 | S18: =100-100/R18 -> 65.879685
O19: fhsp_taupo_king_country_turangi | P19: Taupo | Q19: 0.78545915 | R19: =$R$6*Q19 -> 2.4167974 | S19: =100-100/R19 -> 58.622928 | Y19: Energy consumption per year | AC19: Running cost per year | AG19: GHG emissions | AK19: Running cost over life
B20: Cylinder heat loss (20 degree ambient, 55 temperature rise) | C20: Electric storage water heaters | F20: Gas storage | I20: Heat pump water heater | O20: fhsp_waikato_hamilton | P20: Waikato | Q20: 0.8726003 | R20: =$R$6*Q20 -> 2.684924 | S20: =100-100/R20 -> 62.754998 | Y20: Electric | Z20: Gas storage | AA20: Gas instantaneous | AB20: Heat pump | AC20: Electric | AD20: Gas storage | AE20: Gas instantaneous | AF20: Heat pump | AG20: Electric | AH20: Gas storage | AI20: Gas instantaneous | AJ20: Heat pump | AK20: Electric | AL20: Gas storage | AM20: Gas instantaneous | AN20: Heat pump
B21: Scenario | C21: Tank size (L) | D21: Standing loss (kWh/day) | E21: Standing heatloss per year (kWh/year) | F21: Tank size (L) | G21: Standing loss (kWh/day) | H21: Standing heatloss per year (kWh/year) | I21: Tank size (L) | J21: Standing loss (kWh/day) | K21: Standing heatloss per year (kWh/year) | O21: fhsp_wairarapa_masterton | P21: Wairarapa | Q21: 0.80915968 | R21: =$R$6*Q21 -> 2.4897221 | S21: =100-100/R21 -> 59.834875 | T21: 3.3 | X21: Low | Y21: =VLOOKUP($Y$16,$B$36:$M$54,MATCH(_xlfn.CONCAT($X21," ",Y$20),$B$36:$M$36,0),FALSE)*365+J29*($C$10-VLOOKUP($Y$16,$B$37:$D$54,3,FALSE))*$C$6*52*$Y$17 -> 2265.8465 | Z21: =VLOOKUP($Y$16,$B$36:$M$54,MATCH(_xlfn.CONCAT($X21," ",Z$20),$B$36:$M$36,0),FALSE)*365+J29*(($C$10-VLOOKUP($Y$16,$B$37:$D$54,3,FALSE))*$C$6*(1/$C$11)*52*$Y$17) -> 5521.8576 | AA21: =(J29+L29)*(($C$10-VLOOKUP($Y$16,$B$37:$D$54,3,FALSE))*$C$6*(1/$C$11)*52*$Y$17)+$C$12*365 -> 2295.828 | AB21: =VLOOKUP($Y$16,$B$36:$M$54,MATCH(_xlfn.CONCAT($X21," ",AB$20),$B$36:$M$36,0),FALSE)*365*1/VLOOKUP($Y$16,$B$37:$D$54,2,FALSE)+J29*($C$10-VLOOKUP($Y$16,$B$37:$D$54,3,FALSE))*(1/VLOOKUP($Y$16,$B$37:$D$54,2,FALSE)*$Y$17)*$C$6*52 -> 1498.6874 | AC21: =Y21*$C$7 -> 600.44933 | AD21: =Z21*$C$8+$C$9*365 -> 1052.2358 | AE21: =AA21*$C$8+$C$9*365 -> 729.6328 | AF21: =AB21*$C$7 -> 397.15216 | AG21: =Y21*$C$16 -> 292.2942 | AH21: =Z21*$C$15 -> 1159.5901 | AI21: =AA21*$C$15 -> 482.12388 | AJ21: =AB21*$C$16 -> 193.33067 | AK21: =AC21*12 -> 7205.392 | AL21: =AD21*12 -> 12626.829 | AM21: =AE21*12 -> 8755.5936 | AN21: =AF21*12 -> 4765.8259
B22: Low | C22: 130 | D22: 1.56 | E22: =D22*365 -> 569.4 | F22: 130 | G22: =(0.42+0.02*(F22^(2/3))+0.006*30)*24*0.277778*55/45 -> 9.0709005 | H22: =G22*365 -> 3310.8787 | I22: 170 | J22: =I22^(0.3261)*0.6099+0.2+0.2 -> 3.6554275 | K22: =J22*365 -> 1334.231 | O22: fhsp_wellington_wellington | P22: Wellington | Q22: 1.0055162 | R22: =$R$6*Q22 -> 3.093896 | S22: =100-100/R22 -> 67.678293 | X22: Medium | Y22: =VLOOKUP($Y$16,$B$36:$M$54,MATCH(_xlfn.CONCAT($X22," ",Y$20),$B$36:$M$36,0),FALSE)*365+J30*($C$10-VLOOKUP($Y$16,$B$37:$D$54,3,FALSE))*$C$6*52*$Y$17 -> 4188.6235 | Z22: =VLOOKUP($Y$16,$B$36:$M$54,MATCH(_xlfn.CONCAT($X22," ",Z$20),$B$36:$M$36,0),FALSE)*365+J30*(($C$10-VLOOKUP($Y$16,$B$37:$D$54,3,FALSE))*$C$6*(1/$C$11)*52*$Y$17) -> 8214.9543 | AA22: =(J30+L30)*(($C$10-VLOOKUP($Y$16,$B$37:$D$54,3,FALSE))*$C$6*(1/$C$11)*52*$Y$17)+$C$12*365 -> 4689.9599 | AB22: =VLOOKUP($Y$16,$B$36:$M$54,MATCH(_xlfn.CONCAT($X22," ",AB$20),$B$36:$M$36,0),FALSE)*365*1/VLOOKUP($Y$16,$B$37:$D$54,2,FALSE)+J30*($C$10-VLOOKUP($Y$16,$B$37:$D$54,3,FALSE))*(1/VLOOKUP($Y$16,$B$37:$D$54,2,FALSE)*$Y$17)*$C$6*52 -> 2476.7152 | AC22: =Y22*$C$7 -> 1109.9852 | AD22: =Z22*$C$8+$C$9*365 -> 1321.5454 | AE22: =AA22*$C$8+$C$9*365 -> 969.04599 | AF22: =AB22*$C$7 -> 656.32954 | AG22: =Y22*$C$16 -> 540.33243 | AH22: =Z22*$C$15 -> 1725.1404 | AI22: =AA22*$C$15 -> 984.89157 | AJ22: =AB22*$C$16 -> 319.49627 | AK22: =AC22*12 -> 13319.823 | AL22: =AD22*12 -> 15858.545 | AM22: =AE22*12 -> 11628.552 | AN22: =AF22*12 -> 7875.9545
B23: Medium | C23: 180 | D23: 1.76 | E23: =D23*365 -> 642.4 | F23: 180 | G23: =(0.42+0.02*(F23^(2/3))+0.006*30)*24*0.277778*55/45 -> 10.084117 | H23: =G23*365 -> 3680.7026 | I23: 250 | J23: =I23^(0.3261)*0.6099+0.2+0.2 -> 4.091704 | K23: =J23*365 -> 1493.472 | O23: fhsp_west_coast_hokitika | P23: West Coast | Q23: 0.89504215 | R23: =$R$6*Q23 -> 2.7539758 | S23: =100-100/R23 -> 63.688861 | X23: High | Y23: =VLOOKUP($Y$16,$B$36:$M$54,MATCH(_xlfn.CONCAT($X23," ",Y$20),$B$36:$M$36,0),FALSE)*365+J31*($C$10-VLOOKUP($Y$16,$B$37:$D$54,3,FALSE))*$C$6*52*$Y$17 -> 7988.3201 | Z23: =VLOOKUP($Y$16,$B$36:$M$54,MATCH(_xlfn.CONCAT($X23," ",Z$20),$B$36:$M$36,0),FALSE)*365+J31*(($C$10-VLOOKUP($Y$16,$B$37:$D$54,3,FALSE))*$C$6*(1/$C$11)*52*$Y$17) -> 13328.877 | AA23: =(J31+L31)*(($C$10-VLOOKUP($Y$16,$B$37:$D$54,3,FALSE))*$C$6*(1/$C$11)*52*$Y$17)+$C$12*365 -> 9396.0627 | AB23: =VLOOKUP($Y$16,$B$36:$M$54,MATCH(_xlfn.CONCAT($X23," ",AB$20),$B$36:$M$36,0),FALSE)*365*1/VLOOKUP($Y$16,$B$37:$D$54,2,FALSE)+J31*($C$10-VLOOKUP($Y$16,$B$37:$D$54,3,FALSE))*(1/VLOOKUP($Y$16,$B$37:$D$54,2,FALSE)*$Y$17)*$C$6*52 -> 4294.9648 | AC23: =Y23*$C$7 -> 2116.9048 | AD23: =Z23*$C$8+$C$9*365 -> 1832.9377 | AE23: =AA23*$C$8+$C$9*365 -> 1439.6563 | AF23: =AB23*$C$7 -> 1138.1657 | AG23: =Y23*$C$16 -> 1030.4933 | AH23: =Z23*$C$15 -> 2799.0642 | AI23: =AA23*$C$15 -> 1973.1732 | AJ23: =AB23*$C$16 -> 554.05046 | AK23: =AC23*12 -> 25402.858 | AL23: =AD23*12 -> 21995.252 | AM23: =AE23*12 -> 17275.875 | AN23: =AF23*12 -> 13657.988
B24: High | C24: 250 | D24: 2.16 | E24: =D24*365 -> 788.4 | F24: 260 | G24: =(0.42+0.02*(F24^(2/3))+0.006*30)*24*0.277778*55/45 -> 11.527416 | H24: =G24*365 -> 4207.5069 | I24: 300 | J24: =I24^(0.3261)*0.6099+0.2+0.2 -> 4.3178506 | K24: =J24*365 -> 1576.0155
B25: Comment source | C25: Typically size from sales data | D25: Based on MEPS level with TPR valve 4692 | F25: Based on size from sales data and whats on the market | G25: 6.9.2 based on AS/NZS 4552.2:2010, 45 degree temperature rise, corrected to 55 degree temp rise. Assumed 30 MJ nominal gas consumption | I25: Based on market scan | J25: Based on heat exchanger MEPS in AU 4692. 0.2 added for TPR valve, 0.2 added for two fittings
B27: Water consumption per week per person
B28: Scenario | C28: Showers | D28: Washes on warm wash (assumed hot water connection) | E28: Assumed litres washing machine | F28: Assumed litres shower per min | G28: Assumed shower length | H28: Hot water use shower with temperature adjustment | I28: Washing machine water use with temperature adjustment | J28: Total per person per week (temperature adjustment) | K28: Water use per year | L28: Lost hot water for instantaneous
B29: Low | C29: 3 | D29: 1 | E29: 70 | F29: 10 | G29: 8 | H29: =G29*F29*C29*$C$13/$C$10 -> 136.61538 | I29: =D29*E29*$C$14/$C$10 -> 38.769231 | J29: =H29+I29 -> 175.38462 | K29: =J29*52 -> 9120 | L29: =$C$17*(C29+D29) -> 8
B30: Medium | C30: 5 | D30: 2 | E30: 70 | F30: 10 | G30: 10 | H30: =G30*F30*C30*$C$13/$C$10 -> 284.61538 | I30: =D30*E30*$C$14/$C$10 -> 77.538462 | J30: =H30+I30 -> 362.15385 | K30: =J30*52 -> 18832 | L30: =$C$17*(C30+D30) -> 14
B31: High | C31: 9 | D31: 3 | E31: 70 | F31: 10 | G31: 12 | H31: =G31*F31*C31*$C$13/$C$10 -> 614.76923 | I31: =D31*E31*$C$14/$C$10 -> 116.30769 | J31: =H31+I31 -> 731.07692 | K31: =J31*52 -> 38016 | L31: =$C$17*(C31+D31) -> 24
B32: Comment | C32: created to have variation | D32: created to have variation | E32: Based on typical front load water consumption, could be refined | F32: Typical flow rate | G32: Picked to show variation
B35: Region based metrics. Including how heat loss changes based on climate | E35: Gas water heater low standing losses, assumed outdoor | F35: Gas water heater medium standing losses, assumed outdoor | G35: Gas water heater high standing losses, assumed outdoor | H35: HWPH low standing losses, assumed outdoor | I35: HWPH medium standing losses, assumed outdoor | J35: HWPH high standing losses, assumed outdoor | K35: ESWH low standing losses, assumed indoor | L35: ESWH medium standing losses, assumed indoor | M35: ESWH high standing losses, assumed indoor
B36: Zone | C36: Assumed average COP Heat pump average over a year | D36: Inlet water temperature average over a year | E36: Low Gas storage | F36: Medium Gas storage | G36: High Gas storage | H36: Low Heat pump | I36: Medium Heat pump | J36: High Heat pump | K36: Low Electric | L36: Medium Electric | M36: High Electric
B37: Northland | C37: =VLOOKUP(B37,$P$6:$R$23,3,FALSE) -> 3.0756996 | D37: =VLOOKUP(B37,$Q$87:$R$104,2,FALSE) -> 15.520205 | E37: =($C$10-$D37)/55*$G$22 -> 8.1604781 | F37: =($C$10-$D37)/55*$G$23 -> 9.0720003 | G37: =($C$10-$D37)/55*$G$24 -> 10.37044 | H37: =($C$10-$D37)/55*$J$22 -> 3.2885418 | I37: =($C$10-$D37)/55*$J$23 -> 3.6810304 | J37: =($C$10-$D37)/55*$J$24 -> 3.8844793 | K37: =($C$10-$D37-$C$18)/55*$D$22 -> 1.2616087 | L37: =($C$10-$D37-$C$18)/55*$D$23 -> 1.4233534 | M37: =($C$10-$D37-$C$18)/55*$D$24 -> 1.7468428
B38: Auckland | C38: =VLOOKUP(B38,$P$6:$R$23,3,FALSE) -> 3.0769231 | D38: =VLOOKUP(B38,$Q$87:$R$104,2,FALSE) -> 15.274315 | E38: =($C$10-$D38)/55*$G$22 -> 8.2010316 | F38: =($C$10-$D38)/55*$G$23 -> 9.1170837 | G38: =($C$10-$D38)/55*$G$24 -> 10.421976 | H38: =($C$10-$D38)/55*$J$22 -> 3.3048843 | I38: =($C$10-$D38)/55*$J$23 -> 3.6993233 | J38: =($C$10-$D38)/55*$J$24 -> 3.9037833 | K38: =($C$10-$D38-$C$18)/55*$D$22 -> 1.2685831 | L38: =($C$10-$D38-$C$18)/55*$D$23 -> 1.4312219 | M38: =($C$10-$D38-$C$18)/55*$D$24 -> 1.7564996
B39: Bay of Plenty | C39: =VLOOKUP(B39,$P$6:$R$23,3,FALSE) -> 2.9813398 | D39: =VLOOKUP(B39,$Q$87:$R$104,2,FALSE) -> 14.932991 | E39: =($C$10-$D39)/55*$G$22 -> 8.2573247 | F39: =($C$10-$D39)/55*$G$23 -> 9.1796647 | G39: =($C$10-$D39)/55*$G$24 -> 10.493514 | H39: =($C$10-$D39)/55*$J$22 -> 3.3275695 | I39: =($C$10-$D39)/55*$J$23 -> 3.724716 | J39: =($C$10-$D39)/55*$J$24 -> 3.9305794 | K39: =($C$10-$D39-$C$18)/55*$D$22 -> 1.2782643 | L39: =($C$10-$D39-$C$18)/55*$D$23 -> 1.4421443 | M39: =($C$10-$D39-$C$18)/55*$D$24 -> 1.7699044
B40: Waikato | C40: =VLOOKUP(B40,$P$6:$R$23,3,FALSE) -> 2.684924 | D40: =VLOOKUP(B40,$Q$87:$R$104,2,FALSE) -> 13.536758 | E40: =($C$10-$D40)/55*$G$22 -> 8.487599 | F40: =($C$10-$D40)/55*$G$23 -> 9.4356606 | G40: =($C$10-$D40)/55*$G$24 -> 10.786149 | H40: =($C$10-$D40)/55*$J$22 -> 3.4203664 | I40: =($C$10-$D40)/55*$J$23 -> 3.8285882 | J40: =($C$10-$D40)/55*$J$24 -> 4.0401926 | K40: =($C$10-$D40-$C$18)/55*$D$22 -> 1.3178665 | L40: =($C$10-$D40-$C$18)/55*$D$23 -> 1.4868237 | M40: =($C$10-$D40-$C$18)/55*$D$24 -> 1.8247382
B41: Rotorua | C41: =VLOOKUP(B41,$P$6:$R$23,3,FALSE) -> 2.6523024 | D41: =VLOOKUP(B41,$Q$87:$R$104,2,FALSE) -> 12.184132 | E41: =($C$10-$D41)/55*$G$22 -> 8.7106814 | F41: =($C$10-$D41)/55*$G$23 -> 9.6836612 | G41: =($C$10-$D41)/55*$G$24 -> 11.069645 | H41: =($C$10-$D41)/55*$J$22 -> 3.510265 | I41: =($C$10-$D41)/55*$J$23 -> 3.9292163 | J41: =($C$10-$D41)/55*$J$24 -> 4.1463823 | K41: =($C$10-$D41-$C$18)/55*$D$22 -> 1.3562319 | L41: =($C$10-$D41-$C$18)/55*$D$23 -> 1.5301078 | M41: =($C$10-$D41-$C$18)/55*$D$24 -> 1.8778595
B42: Taupo | C42: =VLOOKUP(B42,$P$6:$R$23,3,FALSE) -> 2.4167974 | D42: =VLOOKUP(B42,$Q$87:$R$104,2,FALSE) -> 11.666553 | E42: =($C$10-$D42)/55*$G$22 -> 8.7960436 | F42: =($C$10-$D42)/55*$G$23 -> 9.7785583 | G42: =($C$10-$D42)/55*$G$24 -> 11.178125 | H42: =($C$10-$D42)/55*$J$22 -> 3.5446645 | I42: =($C$10-$D42)/55*$J$23 -> 3.9677214 | J42: =($C$10-$D42)/55*$J$24 -> 4.1870156 | K42: =($C$10-$D42-$C$18)/55*$D$22 -> 1.3709123 | L42: =($C$10-$D42-$C$18)/55*$D$23 -> 1.5466703 | M42: =($C$10-$D42-$C$18)/55*$D$24 -> 1.8981863
B43: Taranaki | C43: =VLOOKUP(B43,$P$6:$R$23,3,FALSE) -> 2.9308053 | D43: =VLOOKUP(B43,$Q$87:$R$104,2,FALSE) -> 13.594292 | E43: =($C$10-$D43)/55*$G$22 -> 8.4781102 | F43: =($C$10-$D43)/55*$G$23 -> 9.4251119 | G43: =($C$10-$D43)/55*$G$24 -> 10.774091 | H43: =($C$10-$D43)/55*$J$22 -> 3.4165425 | I43: =($C$10-$D43)/55*$J$23 -> 3.824308 | J43: =($C$10-$D43)/55*$J$24 -> 4.0356758 | K43: =($C$10-$D43-$C$18)/55*$D$22 -> 1.3162346 | L43: =($C$10-$D43-$C$18)/55*$D$23 -> 1.4849826 | M43: =($C$10-$D43-$C$18)/55*$D$24 -> 1.8224787
B44: East Coast | C44: =VLOOKUP(B44,$P$6:$R$23,3,FALSE) -> 2.806299 | D44: =VLOOKUP(B44,$Q$87:$R$104,2,FALSE) -> 14.02089 | E44: =($C$10-$D44)/55*$G$22 -> 8.4077533 | F44: =($C$10-$D44)/55*$G$23 -> 9.3468961 | G44: =($C$10-$D44)/55*$G$24 -> 10.68468 | H44: =($C$10-$D44)/55*$J$22 -> 3.3881898 | I44: =($C$10-$D44)/55*$J$23 -> 3.7925714 | J44: =($C$10-$D44)/55*$J$24 -> 4.0021851 | K44: =($C$10-$D44-$C$18)/55*$D$22 -> 1.3041347 | L44: =($C$10-$D44-$C$18)/55*$D$23 -> 1.4713315 | M44: =($C$10-$D44-$C$18)/55*$D$24 -> 1.805725
B45: Wairarapa | C45: =VLOOKUP(B45,$P$6:$R$23,3,FALSE) -> 2.4897221 | D45: =VLOOKUP(B45,$Q$87:$R$104,2,FALSE) -> 12.442123 | E45: =($C$10-$D45)/55*$G$22 -> 8.6681322 | F45: =($C$10-$D45)/55*$G$23 -> 9.6363592 | G45: =($C$10-$D45)/55*$G$24 -> 11.015573 | H45: =($C$10-$D45)/55*$J$22 -> 3.4931183 | I45: =($C$10-$D45)/55*$J$23 -> 3.9100232 | J45: =($C$10-$D45)/55*$J$24 -> 4.1261284 | K45: =($C$10-$D45-$C$18)/55*$D$22 -> 1.3489143 | L45: =($C$10-$D45-$C$18)/55*$D$23 -> 1.5218521 | M45: =($C$10-$D45-$C$18)/55*$D$24 -> 1.8677275
...

Sheet WH - Final
B2: Water heating calculation
B4: Need to factor Rewiring Aotearoa numbers by:
B6: Number of people
B7: Usage (low/medium/high)
B10: Data from Machines tab of Rewiring spreadsheet and EEUD
B12: Note 365.25 days per year in calculation
B14: Options for homes | C14: If Ngas | D14: If LPG | E14: If diesel boiler | F14: If resistive (& ripple control) | G14: If resistive + solar | H14: If heat pump on grid | I14: If heat pump + solar
B15: kWh/day | C15: 6.878 | D15: 6.878 | E15: 9.01 | F15: 7.26 | G15: 7.26 | H15: 2.074 | I15: 2.07
B16: kWh/year | C16: 2512 | D16: 2512 | E16: 3292 | F16: 2652 | G16: 2652 | H16: 758 | I16: 758
B18: Efficiency | C18: 0.95 | D18: 0.95 | F18: 0.9 | H18: 3.15
B20: ESD | C20: =C16 * C18 -> 2386.4 | D20: =D16 * D18 -> 2386.4 | F20: =F16 * F18 -> 2386.8 | H20: =H16 * H18 -> 2387.7
C21: =C20 / 365.25 -> 6.5336071 | D21: =D20 / 365.25 -> 6.5336071 | F21: =F20 / 365.25 -> 6.5347023 | H21: =H20 / 365.25 -> 6.5371663
B23: Values above are determined from RBS and:
B25: Number of homes | C25: 1920300 | D25: Misc tab, cell B2
B27: National ESD | C27: =C20 * C25 / 1000000 -> 4582.6039 | D27: GWh
C28: =C27 * 3.6 -> 16497.374 | D28: TJ | E28: EEUD has 19.316 TJ of fuel use for residential water heating in 2022. Fuel use > ESD makes sense as very few HWHPs.
B30: EEUD fuel consumption | C30: 19316 | D30: TJ
B31: Aggregate efficiency | C31: 0.8
B32: National ESD | C32: =C31 * C30 -> 15452.8
B34: AS/NZS 4234:2021 Heated water systems - Calculation of energy consumption
B39: Key data point is 70% energy saving for HWHP relative to electric in VEU programme (and for HP5-AU climate which is Canberra weather file).
B40: See Matt S's email of Wednesday, September 25, 2024 11:53 AM.
B42: As per analysis in "Climate comparison" tab, Wairarapa is good match to Canberra.
B44: Approximate method for scaling HWHP COP to other climates in NZ is to use the air-air HSPF data.
B48: Average household occupancy | D48: ='WH - Evidence'!I229 -> 2.6
B50: Cold water temperature | C50: 12.5 | D50: degC | E50: Average across climate zones - see WH (2) tab.
B52: Use type | C52: Mean daily volume (L) | D52: Proportion hot | E52: MDV hot (L) | F52: Temperature | G52: Q . Delta T | H52: % Q . Delta T | J52: MDV hot per person (L)
B53: Dishwasher | C53: 6.1 | D53: 0 | E53: =D53 * C53 -> 0 | F53: =$C$50 -> 12.5 | G53: =E53 * ( F53 - $C$50 ) -> 0 | H53: =G53 / $G$60 -> 0 | J53: =E53 / $D$48 -> 0 | L53: Dishwashers are most often internally heated so no draw from HW system.
B54: Washing Machine | C54: 54.1 | D54: 0.5 | E54: =D54 * C54 -> 27.05 | F54: 35 | G54: =E54 * ( F54 - $C$50 ) -> 608.625 | H54: =G54 / $G$60 -> 0.151635 | J54: =E54 / $D$48 -> 10.403846 | L54: Normal/warm wash is 35 deg. Assume 50% of water use is cold (for e.g. rinse) and 50% is 35 degC.
B55: Toilet | C55: 80.7 | D55: 0 | E55: =D55 * C55 -> 0 | F55: =$C$50 -> 12.5 | G55: =E55 * ( F55 - $C$50 ) -> 0 | H55: =G55 / $G$60 -> 0 | J55: =E55 / $D$48 -> 0 | L55: All cold
B56: Shower | C56: 102.1 | D56: 1 | E56: =D56 * C56 -> 102.1 | F56: 37 | G56: =E56 * ( F56 - $C$50 ) -> 2501.45 | H56: =G56 / $G$60 -> 0.62322018 | J56: =E56 / $D$48 -> 39.269231 | L56: All 37 degC.
B57: Tap | C57: 46.3 | D57: 0.5 | E57: =D57 * C57 -> 23.15 | F57: 40 | G57: =E57 * ( F57 - $C$50 ) -> 636.625 | H57: =G57 / $G$60 -> 0.15861102 | J57: =E57 / $D$48 -> 8.9038462 | L57: Assume 50/50 cold/40 degC.
B58: High Flow/Outdoor* | C58: 21.8 | D58: 0.5 | E58: =D58 * C58 -> 10.9 | F58: 37 | G58: =E58 * ( F58 - $C$50 ) -> 267.05 | H58: =G58 / $G$60 -> 0.06653379 | J58: =E58 / $D$48 -> 4.1923077 | L58: Assume winter use is laundry tubs/baths i.e. 0% outdoor. Assume this is constant through the year. Assume 50% is at 37 degC.
B59: Undefined | C59: 8.3 | D59: 0 | E59: =D59 * C59 -> 0 | F59: =$C$50 -> 12.5 | G59: =E59 * ( F59 - $C$50 ) -> 0 | H59: =G59 / $G$60 -> 0 | J59: =E59 / $D$48 -> 0 | L59: Ignore.
C60: =SUM( C53:C59 ) -> 319.4 | E60: =SUM( E53:E59 ) -> 163.2 | G60: =SUM( G53:G59 ) -> 4013.75
B62: * High Flow/Outdoor mean daily volume is from winter season.
B66: Top-down and bottom-up reconciliation
B68: Specific heat capacity | C68: 4184 | D68: J / ( kg K )
C69: =C68 / 1000000 / 3.6 -> 0.0011622222 | D69: kWh / ( kg K )
B71: Weekly per person | C71: 403 | D71: L | E71: From water use data
...

Sheet WH - Final (2)
B3: Constants
B5: Specific heat capacity | C5: 4184 | D5: J / ( kg K )
C6: =C5 / 1000000 / 3.6 -> 0.0011622222 | D6: kWh / ( kg K )
B8: Density | C8: 1 | D8: kg / L
B11: Per-person demand
B13: Showering
B15: Scenario | C15: Per week | D15: Per shower | E15: Flow | F15: Volume | G15: Volume | H15: Ratio | J15: Temperature
C16: [] | D16: [min] | E16: [L/min] | F16: [L/use] | G16: [L/day] | J16: [degC]
B17: Low | C17: 5 | D17: 5 | E17: 5 | F17: =D17 * E17 -> 25 | G17: =C17 * D17 * E17 / 7 -> 17.857143 | H17: =G17 / $G$18 -> 0.42517007 | J17: 37
B18: Medium | C18: 6 | D18: 7 | E18: 7 | F18: =D18 * E18 -> 49 | G18: =C18 * D18 * E18 / 7 -> 42 | H18: =G18 / $G$18 -> 1 | J18: 37
B19: High | C19: 7 | D19: 9 | E19: 9 | F19: =D19 * E19 -> 81 | G19: =C19 * D19 * E19 / 7 -> 81 | H19: =G19 / $G$18 -> 1.9285714 | J19: 37
B21: Other - assumed to not vary under low/medium/high scenarios
C23: Volume | D23: Temperature
C24: [L/day] | D24: [degC]
B25: Washing Machine | C25: 10.403846 | D25: 35
B26: Tap | C26: 8.9038462 | D26: 40
B27: High Flow/Outdoor* | C27: 4.1923077 | D27: 37
B29: * High Flow/Outdoor mean daily volume is from winter season.
B32: Climate
B34: Zone | C34: Climate zone code | D34: Average Tc | F34: NZBC | J34: NIWA to NZBC map in different order - used for XLOOKUP at left and below in HWHP COP table | T34: Mappings based on:
D35: [degC]
B36: Northland | C36: NL | D36: 15.520205 | F36: =_xlfn.XLOOKUP( B36, $J$36:$J$53, $K$36:$K$53 ) -> 1 | J36: Northland | K36: 1 | T36: https://www.building.govt.nz/assets/Uploads/building-code-compliance/h1-energy-efficiency/asvm/h1-energy-efficiency-as1-5th-edition-amendment-1.pdf
B37: Auckland | C37: AK | D37: 15.274315 | F37: =_xlfn.XLOOKUP( B37, $J$36:$J$53, $K$36:$K$53 ) -> 1 | J37: Auckland | K37: 1
B38: Hamilton | C38: HN | D38: 13.536758 | F38: =_xlfn.XLOOKUP( B38, $J$36:$J$53, $K$36:$K$53 ) -> 2 | J38: Hamilton | K38: 2 | T38: See table on p. 23 and map on p. 24.
B39: Bay of Plenty | C39: BP | D39: 14.932991 | F39: =_xlfn.XLOOKUP( B39, $J$36:$J$53, $K$36:$K$53 ) -> 1 | J39: Taupo | K39: 4
B40: Rotorua | C40: RR | D40: 12.184132 | F40: =_xlfn.XLOOKUP( B40, $J$36:$J$53, $K$36:$K$53 ) -> 4 | J40: Bay of Plenty | K40: 1
B41: Taupo | C41: TP | D41: 11.666553 | F41: =_xlfn.XLOOKUP( B41, $J$36:$J$53, $K$36:$K$53 ) -> 4 | J41: Rotorua | K41: 4
